ERROR 2025-07-19 10:42:50,855 log 10512 21104 Internal Server Error: /doctor/doctor-profile/
Traceback (most recent call last):
  File "D:\DOCNET\docnet-backend\venv\Lib\site-packages\asgiref\sync.py", line 518, in thread_handler
    raise exc_info[1]
  File "D:\DOCNET\docnet-backend\venv\Lib\site-packages\django\core\handlers\exception.py", line 42, in inner
    response = await get_response(request)
               ^^^^^^^^^^^^^^^^^^^^^^^^^^^
  File "D:\DOCNET\docnet-backend\venv\Lib\site-packages\django\core\handlers\base.py", line 235, in _get_response_async
    callback, callback_args, callback_kwargs = self.resolve_request(request)
                                               ~~~~~~~~~~~~~~~~~~~~^^^^^^^^^
  File "D:\DOCNET\docnet-backend\venv\Lib\site-packages\django\core\handlers\base.py", line 313, in resolve_request
    resolver_match = resolver.resolve(request.path_info)
  File "D:\DOCNET\docnet-backend\venv\Lib\site-packages\django\urls\resolvers.py", line 666, in resolve
    for pattern in self.url_patterns:
                   ^^^^^^^^^^^^^^^^^
  File "D:\DOCNET\docnet-backend\venv\Lib\site-packages\django\utils\functional.py", line 47, in __get__
    res = instance.__dict__[self.name] = self.func(instance)
                                         ~~~~~~~~~^^^^^^^^^^
  File "D:\DOCNET\docnet-backend\venv\Lib\site-packages\django\urls\resolvers.py", line 718, in url_patterns
    patterns = getattr(self.urlconf_module, "urlpatterns", self.urlconf_module)
                       ^^^^^^^^^^^^^^^^^^^
  File "D:\DOCNET\docnet-backend\venv\Lib\site-packages\django\utils\functional.py", line 47, in __get__
    res = instance.__dict__[self.name] = self.func(instance)
                                         ~~~~~~~~~^^^^^^^^^^
  File "D:\DOCNET\docnet-backend\venv\Lib\site-packages\django\urls\resolvers.py", line 711, in urlconf_module
    return import_module(self.urlconf_name)
  File "C:\Users\ASUS\AppData\Local\Programs\Python\Python313\Lib\importlib\__init__.py", line 88, in import_module
    return _bootstrap._gcd_import(name[level:], package, level)
           ~~~~~~~~~~~~~~~~~~~~~~^^^^^^^^^^^^^^^^^^^^^^^^^^^^^^
  File "<frozen importlib._bootstrap>", line 1387, in _gcd_import
  File "<frozen importlib._bootstrap>", line 1360, in _find_and_load
  File "<frozen importlib._bootstrap>", line 1331, in _find_and_load_unlocked
  File "<frozen importlib._bootstrap>", line 935, in _load_unlocked
  File "<frozen importlib._bootstrap_external>", line 1026, in exec_module
  File "<frozen importlib._bootstrap>", line 488, in _call_with_frames_removed
  File "D:\DOCNET\docnet-backend\config\urls.py", line 33, in <module>
    path('core/',include('core.urls')), #admin
                 ~~~~~~~^^^^^^^^^^^^^
  File "D:\DOCNET\docnet-backend\venv\Lib\site-packages\django\urls\conf.py", line 39, in include
    urlconf_module = import_module(urlconf_module)
  File "C:\Users\ASUS\AppData\Local\Programs\Python\Python313\Lib\importlib\__init__.py", line 88, in import_module
    return _bootstrap._gcd_import(name[level:], package, level)
           ~~~~~~~~~~~~~~~~~~~~~~^^^^^^^^^^^^^^^^^^^^^^^^^^^^^^
  File "<frozen importlib._bootstrap>", line 1387, in _gcd_import
  File "<frozen importlib._bootstrap>", line 1360, in _find_and_load
  File "<frozen importlib._bootstrap>", line 1331, in _find_and_load_unlocked
  File "<frozen importlib._bootstrap>", line 935, in _load_unlocked
  File "<frozen importlib._bootstrap_external>", line 1026, in exec_module
  File "<frozen importlib._bootstrap>", line 488, in _call_with_frames_removed
  File "D:\DOCNET\docnet-backend\core\urls.py", line 3, in <module>
    from .views import AdminPaymentHistoryAPIView,DoctorEarningsReportAPIView,AdminPaymentCSVExportView,AdminPaymentPDFExportView,DoctorReportsView,MarkReportAsReadView
ImportError: cannot import name 'ApproveWithdrawalView' from 'core.views' (D:\DOCNET\docnet-backend\core\views.py)

During handling of the above exception, another exception occurred:

Traceback (most recent call last):
  File "D:\DOCNET\docnet-backend\venv\Lib\site-packages\asgiref\sync.py", line 518, in thread_handler
    raise exc_info[1]
  File "D:\DOCNET\docnet-backend\venv\Lib\site-packages\django\core\handlers\exception.py", line 42, in inner
    response = await get_response(request)
               ^^^^^^^^^^^^^^^^^^^^^^^^^^^
  File "D:\DOCNET\docnet-backend\venv\Lib\site-packages\allauth\account\middleware.py", line 26, in middleware
    response = await get_response(request)
               ^^^^^^^^^^^^^^^^^^^^^^^^^^^
  File "D:\DOCNET\docnet-backend\venv\Lib\site-packages\django\core\handlers\exception.py", line 44, in inner
    response = await sync_to_async(
               ^^^^^^^^^^^^^^^^^^^^
        response_for_exception, thread_sensitive=False
        ^^^^^^^^^^^^^^^^^^^^^^^^^^^^^^^^^^^^^^^^^^^^^^
    )(request, exc)
    ^^^^^^^^^^^^^^^
  File "D:\DOCNET\docnet-backend\venv\Lib\site-packages\asgiref\sync.py", line 468, in __call__
    ret = await asyncio.shield(exec_coro)
          ^^^^^^^^^^^^^^^^^^^^^^^^^^^^^^^
  File "C:\Users\ASUS\AppData\Local\Programs\Python\Python313\Lib\concurrent\futures\thread.py", line 59, in run
    result = self.fn(*self.args, **self.kwargs)
  File "D:\DOCNET\docnet-backend\venv\Lib\site-packages\asgiref\sync.py", line 520, in thread_handler
    return func(*args, **kwargs)
  File "D:\DOCNET\docnet-backend\venv\Lib\site-packages\django\core\handlers\exception.py", line 140, in response_for_exception
    response = handle_uncaught_exception(
        request, get_resolver(get_urlconf()), sys.exc_info()
    )
  File "D:\DOCNET\docnet-backend\venv\Lib\site-packages\django\core\handlers\exception.py", line 181, in handle_uncaught_exception
    return debug.technical_500_response(request, *exc_info)
           ~~~~~~~~~~~~~~~~~~~~~~~~~~~~^^^^^^^^^^^^^^^^^^^^
  File "D:\DOCNET\docnet-backend\venv\Lib\site-packages\django\views\debug.py", line 69, in technical_500_response
    html = reporter.get_traceback_html()
  File "D:\DOCNET\docnet-backend\venv\Lib\site-packages\django\views\debug.py", line 428, in get_traceback_html
    c = Context(self.get_traceback_data(), use_l10n=False)
                ~~~~~~~~~~~~~~~~~~~~~~~^^
  File "D:\DOCNET\docnet-backend\venv\Lib\site-packages\django\views\debug.py", line 411, in get_traceback_data
    c["raising_view_name"] = get_caller(self.request)
                             ~~~~~~~~~~^^^^^^^^^^^^^^
  File "D:\DOCNET\docnet-backend\venv\Lib\site-packages\django\views\debug.py", line 102, in get_caller
    resolver_match = resolve(request.path)
  File "D:\DOCNET\docnet-backend\venv\Lib\site-packages\django\urls\base.py", line 25, in resolve
    return get_resolver(urlconf).resolve(path)
           ~~~~~~~~~~~~~~~~~~~~~~~~~~~~~^^^^^^
  File "D:\DOCNET\docnet-backend\venv\Lib\site-packages\django\urls\resolvers.py", line 666, in resolve
    for pattern in self.url_patterns:
                   ^^^^^^^^^^^^^^^^^
  File "D:\DOCNET\docnet-backend\venv\Lib\site-packages\django\utils\functional.py", line 47, in __get__
    res = instance.__dict__[self.name] = self.func(instance)
                                         ~~~~~~~~~^^^^^^^^^^
  File "D:\DOCNET\docnet-backend\venv\Lib\site-packages\django\urls\resolvers.py", line 718, in url_patterns
    patterns = getattr(self.urlconf_module, "urlpatterns", self.urlconf_module)
                       ^^^^^^^^^^^^^^^^^^^
  File "D:\DOCNET\docnet-backend\venv\Lib\site-packages\django\utils\functional.py", line 47, in __get__
    res = instance.__dict__[self.name] = self.func(instance)
                                         ~~~~~~~~~^^^^^^^^^^
  File "D:\DOCNET\docnet-backend\venv\Lib\site-packages\django\urls\resolvers.py", line 711, in urlconf_module
    return import_module(self.urlconf_name)
  File "C:\Users\ASUS\AppData\Local\Programs\Python\Python313\Lib\importlib\__init__.py", line 88, in import_module
    return _bootstrap._gcd_import(name[level:], package, level)
           ~~~~~~~~~~~~~~~~~~~~~~^^^^^^^^^^^^^^^^^^^^^^^^^^^^^^
  File "<frozen importlib._bootstrap>", line 1387, in _gcd_import
  File "<frozen importlib._bootstrap>", line 1360, in _find_and_load
  File "<frozen importlib._bootstrap>", line 1331, in _find_and_load_unlocked
  File "<frozen importlib._bootstrap>", line 935, in _load_unlocked
  File "<frozen importlib._bootstrap_external>", line 1026, in exec_module
  File "<frozen importlib._bootstrap>", line 488, in _call_with_frames_removed
  File "D:\DOCNET\docnet-backend\config\urls.py", line 33, in <module>
    path('core/',include('core.urls')), #admin
                 ~~~~~~~^^^^^^^^^^^^^
  File "D:\DOCNET\docnet-backend\venv\Lib\site-packages\django\urls\conf.py", line 39, in include
    urlconf_module = import_module(urlconf_module)
  File "C:\Users\ASUS\AppData\Local\Programs\Python\Python313\Lib\importlib\__init__.py", line 88, in import_module
    return _bootstrap._gcd_import(name[level:], package, level)
           ~~~~~~~~~~~~~~~~~~~~~~^^^^^^^^^^^^^^^^^^^^^^^^^^^^^^
  File "<frozen importlib._bootstrap>", line 1387, in _gcd_import
  File "<frozen importlib._bootstrap>", line 1360, in _find_and_load
  File "<frozen importlib._bootstrap>", line 1331, in _find_and_load_unlocked
  File "<frozen importlib._bootstrap>", line 935, in _load_unlocked
  File "<frozen importlib._bootstrap_external>", line 1026, in exec_module
  File "<frozen importlib._bootstrap>", line 488, in _call_with_frames_removed
  File "D:\DOCNET\docnet-backend\core\urls.py", line 3, in <module>
    from .views import AdminPaymentHistoryAPIView,DoctorEarningsReportAPIView,AdminPaymentCSVExportView,AdminPaymentPDFExportView,DoctorReportsView,MarkReportAsReadView
ImportError: cannot import name 'ApproveWithdrawalView' from 'core.views' (D:\DOCNET\docnet-backend\core\views.py)

During handling of the above exception, another exception occurred:

Traceback (most recent call last):
  File "D:\DOCNET\docnet-backend\venv\Lib\site-packages\asgiref\sync.py", line 518, in thread_handler
    raise exc_info[1]
  File "D:\DOCNET\docnet-backend\venv\Lib\site-packages\django\core\handlers\exception.py", line 42, in inner
    response = await get_response(request)
               ^^^^^^^^^^^^^^^^^^^^^^^^^^^
  File "D:\DOCNET\docnet-backend\venv\Lib\site-packages\corsheaders\middleware.py", line 67, in __acall__
    response = await result
               ^^^^^^^^^^^^
  File "D:\DOCNET\docnet-backend\venv\Lib\site-packages\django\core\handlers\exception.py", line 44, in inner
    response = await sync_to_async(
               ^^^^^^^^^^^^^^^^^^^^
        response_for_exception, thread_sensitive=False
        ^^^^^^^^^^^^^^^^^^^^^^^^^^^^^^^^^^^^^^^^^^^^^^
    )(request, exc)
    ^^^^^^^^^^^^^^^
  File "D:\DOCNET\docnet-backend\venv\Lib\site-packages\asgiref\sync.py", line 468, in __call__
    ret = await asyncio.shield(exec_coro)
          ^^^^^^^^^^^^^^^^^^^^^^^^^^^^^^^
  File "C:\Users\ASUS\AppData\Local\Programs\Python\Python313\Lib\concurrent\futures\thread.py", line 59, in run
    result = self.fn(*self.args, **self.kwargs)
  File "D:\DOCNET\docnet-backend\venv\Lib\site-packages\asgiref\sync.py", line 520, in thread_handler
    return func(*args, **kwargs)
  File "D:\DOCNET\docnet-backend\venv\Lib\site-packages\django\core\handlers\exception.py", line 140, in response_for_exception
    response = handle_uncaught_exception(
        request, get_resolver(get_urlconf()), sys.exc_info()
    )
  File "D:\DOCNET\docnet-backend\venv\Lib\site-packages\django\core\handlers\exception.py", line 181, in handle_uncaught_exception
    return debug.technical_500_response(request, *exc_info)
           ~~~~~~~~~~~~~~~~~~~~~~~~~~~~^^^^^^^^^^^^^^^^^^^^
  File "D:\DOCNET\docnet-backend\venv\Lib\site-packages\django\views\debug.py", line 69, in technical_500_response
    html = reporter.get_traceback_html()
  File "D:\DOCNET\docnet-backend\venv\Lib\site-packages\django\views\debug.py", line 428, in get_traceback_html
    c = Context(self.get_traceback_data(), use_l10n=False)
                ~~~~~~~~~~~~~~~~~~~~~~~^^
  File "D:\DOCNET\docnet-backend\venv\Lib\site-packages\django\views\debug.py", line 411, in get_traceback_data
    c["raising_view_name"] = get_caller(self.request)
                             ~~~~~~~~~~^^^^^^^^^^^^^^
  File "D:\DOCNET\docnet-backend\venv\Lib\site-packages\django\views\debug.py", line 102, in get_caller
    resolver_match = resolve(request.path)
  File "D:\DOCNET\docnet-backend\venv\Lib\site-packages\django\urls\base.py", line 25, in resolve
    return get_resolver(urlconf).resolve(path)
           ~~~~~~~~~~~~~~~~~~~~~~~~~~~~~^^^^^^
  File "D:\DOCNET\docnet-backend\venv\Lib\site-packages\django\urls\resolvers.py", line 666, in resolve
    for pattern in self.url_patterns:
                   ^^^^^^^^^^^^^^^^^
  File "D:\DOCNET\docnet-backend\venv\Lib\site-packages\django\utils\functional.py", line 47, in __get__
    res = instance.__dict__[self.name] = self.func(instance)
                                         ~~~~~~~~~^^^^^^^^^^
  File "D:\DOCNET\docnet-backend\venv\Lib\site-packages\django\urls\resolvers.py", line 718, in url_patterns
    patterns = getattr(self.urlconf_module, "urlpatterns", self.urlconf_module)
                       ^^^^^^^^^^^^^^^^^^^
  File "D:\DOCNET\docnet-backend\venv\Lib\site-packages\django\utils\functional.py", line 47, in __get__
    res = instance.__dict__[self.name] = self.func(instance)
                                         ~~~~~~~~~^^^^^^^^^^
  File "D:\DOCNET\docnet-backend\venv\Lib\site-packages\django\urls\resolvers.py", line 711, in urlconf_module
    return import_module(self.urlconf_name)
  File "C:\Users\ASUS\AppData\Local\Programs\Python\Python313\Lib\importlib\__init__.py", line 88, in import_module
    return _bootstrap._gcd_import(name[level:], package, level)
           ~~~~~~~~~~~~~~~~~~~~~~^^^^^^^^^^^^^^^^^^^^^^^^^^^^^^
  File "<frozen importlib._bootstrap>", line 1387, in _gcd_import
  File "<frozen importlib._bootstrap>", line 1360, in _find_and_load
  File "<frozen importlib._bootstrap>", line 1331, in _find_and_load_unlocked
  File "<frozen importlib._bootstrap>", line 935, in _load_unlocked
  File "<frozen importlib._bootstrap_external>", line 1026, in exec_module
  File "<frozen importlib._bootstrap>", line 488, in _call_with_frames_removed
  File "D:\DOCNET\docnet-backend\config\urls.py", line 33, in <module>
    path('core/',include('core.urls')), #admin
                 ~~~~~~~^^^^^^^^^^^^^
  File "D:\DOCNET\docnet-backend\venv\Lib\site-packages\django\urls\conf.py", line 39, in include
    urlconf_module = import_module(urlconf_module)
  File "C:\Users\ASUS\AppData\Local\Programs\Python\Python313\Lib\importlib\__init__.py", line 88, in import_module
    return _bootstrap._gcd_import(name[level:], package, level)
           ~~~~~~~~~~~~~~~~~~~~~~^^^^^^^^^^^^^^^^^^^^^^^^^^^^^^
  File "<frozen importlib._bootstrap>", line 1387, in _gcd_import
  File "<frozen importlib._bootstrap>", line 1360, in _find_and_load
  File "<frozen importlib._bootstrap>", line 1331, in _find_and_load_unlocked
  File "<frozen importlib._bootstrap>", line 935, in _load_unlocked
  File "<frozen importlib._bootstrap_external>", line 1026, in exec_module
  File "<frozen importlib._bootstrap>", line 488, in _call_with_frames_removed
  File "D:\DOCNET\docnet-backend\core\urls.py", line 3, in <module>
    from .views import AdminPaymentHistoryAPIView,DoctorEarningsReportAPIView,AdminPaymentCSVExportView,AdminPaymentPDFExportView,DoctorReportsView,MarkReportAsReadView
ImportError: cannot import name 'ApproveWithdrawalView' from 'core.views' (D:\DOCNET\docnet-backend\core\views.py)

During handling of the above exception, another exception occurred:

Traceback (most recent call last):
  File "D:\DOCNET\docnet-backend\venv\Lib\site-packages\asgiref\sync.py", line 518, in thread_handler
    raise exc_info[1]
  File "D:\DOCNET\docnet-backend\venv\Lib\site-packages\django\core\handlers\exception.py", line 42, in inner
    response = await get_response(request)
               ^^^^^^^^^^^^^^^^^^^^^^^^^^^
  File "D:\DOCNET\docnet-backend\venv\Lib\site-packages\django\utils\deprecation.py", line 136, in __acall__
    response = response or await self.get_response(request)
                           ^^^^^^^^^^^^^^^^^^^^^^^^^^^^^^^^
  File "D:\DOCNET\docnet-backend\venv\Lib\site-packages\django\core\handlers\exception.py", line 44, in inner
    response = await sync_to_async(
               ^^^^^^^^^^^^^^^^^^^^
        response_for_exception, thread_sensitive=False
        ^^^^^^^^^^^^^^^^^^^^^^^^^^^^^^^^^^^^^^^^^^^^^^
    )(request, exc)
    ^^^^^^^^^^^^^^^
  File "D:\DOCNET\docnet-backend\venv\Lib\site-packages\asgiref\sync.py", line 468, in __call__
    ret = await asyncio.shield(exec_coro)
          ^^^^^^^^^^^^^^^^^^^^^^^^^^^^^^^
  File "C:\Users\ASUS\AppData\Local\Programs\Python\Python313\Lib\concurrent\futures\thread.py", line 59, in run
    result = self.fn(*self.args, **self.kwargs)
  File "D:\DOCNET\docnet-backend\venv\Lib\site-packages\asgiref\sync.py", line 520, in thread_handler
    return func(*args, **kwargs)
  File "D:\DOCNET\docnet-backend\venv\Lib\site-packages\django\core\handlers\exception.py", line 140, in response_for_exception
    response = handle_uncaught_exception(
        request, get_resolver(get_urlconf()), sys.exc_info()
    )
  File "D:\DOCNET\docnet-backend\venv\Lib\site-packages\django\core\handlers\exception.py", line 181, in handle_uncaught_exception
    return debug.technical_500_response(request, *exc_info)
           ~~~~~~~~~~~~~~~~~~~~~~~~~~~~^^^^^^^^^^^^^^^^^^^^
  File "D:\DOCNET\docnet-backend\venv\Lib\site-packages\django\views\debug.py", line 69, in technical_500_response
    html = reporter.get_traceback_html()
  File "D:\DOCNET\docnet-backend\venv\Lib\site-packages\django\views\debug.py", line 428, in get_traceback_html
    c = Context(self.get_traceback_data(), use_l10n=False)
                ~~~~~~~~~~~~~~~~~~~~~~~^^
  File "D:\DOCNET\docnet-backend\venv\Lib\site-packages\django\views\debug.py", line 411, in get_traceback_data
    c["raising_view_name"] = get_caller(self.request)
                             ~~~~~~~~~~^^^^^^^^^^^^^^
  File "D:\DOCNET\docnet-backend\venv\Lib\site-packages\django\views\debug.py", line 102, in get_caller
    resolver_match = resolve(request.path)
  File "D:\DOCNET\docnet-backend\venv\Lib\site-packages\django\urls\base.py", line 25, in resolve
    return get_resolver(urlconf).resolve(path)
           ~~~~~~~~~~~~~~~~~~~~~~~~~~~~~^^^^^^
  File "D:\DOCNET\docnet-backend\venv\Lib\site-packages\django\urls\resolvers.py", line 666, in resolve
    for pattern in self.url_patterns:
                   ^^^^^^^^^^^^^^^^^
  File "D:\DOCNET\docnet-backend\venv\Lib\site-packages\django\utils\functional.py", line 47, in __get__
    res = instance.__dict__[self.name] = self.func(instance)
                                         ~~~~~~~~~^^^^^^^^^^
  File "D:\DOCNET\docnet-backend\venv\Lib\site-packages\django\urls\resolvers.py", line 718, in url_patterns
    patterns = getattr(self.urlconf_module, "urlpatterns", self.urlconf_module)
                       ^^^^^^^^^^^^^^^^^^^
  File "D:\DOCNET\docnet-backend\venv\Lib\site-packages\django\utils\functional.py", line 47, in __get__
    res = instance.__dict__[self.name] = self.func(instance)
                                         ~~~~~~~~~^^^^^^^^^^
  File "D:\DOCNET\docnet-backend\venv\Lib\site-packages\django\urls\resolvers.py", line 711, in urlconf_module
    return import_module(self.urlconf_name)
  File "C:\Users\ASUS\AppData\Local\Programs\Python\Python313\Lib\importlib\__init__.py", line 88, in import_module
    return _bootstrap._gcd_import(name[level:], package, level)
           ~~~~~~~~~~~~~~~~~~~~~~^^^^^^^^^^^^^^^^^^^^^^^^^^^^^^
  File "<frozen importlib._bootstrap>", line 1387, in _gcd_import
  File "<frozen importlib._bootstrap>", line 1360, in _find_and_load
  File "<frozen importlib._bootstrap>", line 1331, in _find_and_load_unlocked
  File "<frozen importlib._bootstrap>", line 935, in _load_unlocked
  File "<frozen importlib._bootstrap_external>", line 1026, in exec_module
  File "<frozen importlib._bootstrap>", line 488, in _call_with_frames_removed
  File "D:\DOCNET\docnet-backend\config\urls.py", line 33, in <module>
    path('core/',include('core.urls')), #admin
                 ~~~~~~~^^^^^^^^^^^^^
  File "D:\DOCNET\docnet-backend\venv\Lib\site-packages\django\urls\conf.py", line 39, in include
    urlconf_module = import_module(urlconf_module)
  File "C:\Users\ASUS\AppData\Local\Programs\Python\Python313\Lib\importlib\__init__.py", line 88, in import_module
    return _bootstrap._gcd_import(name[level:], package, level)
           ~~~~~~~~~~~~~~~~~~~~~~^^^^^^^^^^^^^^^^^^^^^^^^^^^^^^
  File "<frozen importlib._bootstrap>", line 1387, in _gcd_import
  File "<frozen importlib._bootstrap>", line 1360, in _find_and_load
  File "<frozen importlib._bootstrap>", line 1331, in _find_and_load_unlocked
  File "<frozen importlib._bootstrap>", line 935, in _load_unlocked
  File "<frozen importlib._bootstrap_external>", line 1026, in exec_module
  File "<frozen importlib._bootstrap>", line 488, in _call_with_frames_removed
  File "D:\DOCNET\docnet-backend\core\urls.py", line 3, in <module>
    from .views import AdminPaymentHistoryAPIView,DoctorEarningsReportAPIView,AdminPaymentCSVExportView,AdminPaymentPDFExportView,DoctorReportsView,MarkReportAsReadView
ImportError: cannot import name 'ApproveWithdrawalView' from 'core.views' (D:\DOCNET\docnet-backend\core\views.py)

During handling of the above exception, another exception occurred:

Traceback (most recent call last):
  File "D:\DOCNET\docnet-backend\venv\Lib\site-packages\asgiref\sync.py", line 518, in thread_handler
    raise exc_info[1]
  File "D:\DOCNET\docnet-backend\venv\Lib\site-packages\django\core\handlers\exception.py", line 42, in inner
    response = await get_response(request)
               ^^^^^^^^^^^^^^^^^^^^^^^^^^^
  File "D:\DOCNET\docnet-backend\venv\Lib\site-packages\django\utils\deprecation.py", line 136, in __acall__
    response = response or await self.get_response(request)
                           ^^^^^^^^^^^^^^^^^^^^^^^^^^^^^^^^
  File "D:\DOCNET\docnet-backend\venv\Lib\site-packages\django\core\handlers\exception.py", line 44, in inner
    response = await sync_to_async(
               ^^^^^^^^^^^^^^^^^^^^
        response_for_exception, thread_sensitive=False
        ^^^^^^^^^^^^^^^^^^^^^^^^^^^^^^^^^^^^^^^^^^^^^^
    )(request, exc)
    ^^^^^^^^^^^^^^^
  File "D:\DOCNET\docnet-backend\venv\Lib\site-packages\asgiref\sync.py", line 468, in __call__
    ret = await asyncio.shield(exec_coro)
          ^^^^^^^^^^^^^^^^^^^^^^^^^^^^^^^
  File "C:\Users\ASUS\AppData\Local\Programs\Python\Python313\Lib\concurrent\futures\thread.py", line 59, in run
    result = self.fn(*self.args, **self.kwargs)
  File "D:\DOCNET\docnet-backend\venv\Lib\site-packages\asgiref\sync.py", line 520, in thread_handler
    return func(*args, **kwargs)
  File "D:\DOCNET\docnet-backend\venv\Lib\site-packages\django\core\handlers\exception.py", line 140, in response_for_exception
    response = handle_uncaught_exception(
        request, get_resolver(get_urlconf()), sys.exc_info()
    )
  File "D:\DOCNET\docnet-backend\venv\Lib\site-packages\django\core\handlers\exception.py", line 181, in handle_uncaught_exception
    return debug.technical_500_response(request, *exc_info)
           ~~~~~~~~~~~~~~~~~~~~~~~~~~~~^^^^^^^^^^^^^^^^^^^^
  File "D:\DOCNET\docnet-backend\venv\Lib\site-packages\django\views\debug.py", line 69, in technical_500_response
    html = reporter.get_traceback_html()
  File "D:\DOCNET\docnet-backend\venv\Lib\site-packages\django\views\debug.py", line 428, in get_traceback_html
    c = Context(self.get_traceback_data(), use_l10n=False)
                ~~~~~~~~~~~~~~~~~~~~~~~^^
  File "D:\DOCNET\docnet-backend\venv\Lib\site-packages\django\views\debug.py", line 411, in get_traceback_data
    c["raising_view_name"] = get_caller(self.request)
                             ~~~~~~~~~~^^^^^^^^^^^^^^
  File "D:\DOCNET\docnet-backend\venv\Lib\site-packages\django\views\debug.py", line 102, in get_caller
    resolver_match = resolve(request.path)
  File "D:\DOCNET\docnet-backend\venv\Lib\site-packages\django\urls\base.py", line 25, in resolve
    return get_resolver(urlconf).resolve(path)
           ~~~~~~~~~~~~~~~~~~~~~~~~~~~~~^^^^^^
  File "D:\DOCNET\docnet-backend\venv\Lib\site-packages\django\urls\resolvers.py", line 666, in resolve
    for pattern in self.url_patterns:
                   ^^^^^^^^^^^^^^^^^
  File "D:\DOCNET\docnet-backend\venv\Lib\site-packages\django\utils\functional.py", line 47, in __get__
    res = instance.__dict__[self.name] = self.func(instance)
                                         ~~~~~~~~~^^^^^^^^^^
  File "D:\DOCNET\docnet-backend\venv\Lib\site-packages\django\urls\resolvers.py", line 718, in url_patterns
    patterns = getattr(self.urlconf_module, "urlpatterns", self.urlconf_module)
                       ^^^^^^^^^^^^^^^^^^^
  File "D:\DOCNET\docnet-backend\venv\Lib\site-packages\django\utils\functional.py", line 47, in __get__
    res = instance.__dict__[self.name] = self.func(instance)
                                         ~~~~~~~~~^^^^^^^^^^
  File "D:\DOCNET\docnet-backend\venv\Lib\site-packages\django\urls\resolvers.py", line 711, in urlconf_module
    return import_module(self.urlconf_name)
  File "C:\Users\ASUS\AppData\Local\Programs\Python\Python313\Lib\importlib\__init__.py", line 88, in import_module
    return _bootstrap._gcd_import(name[level:], package, level)
           ~~~~~~~~~~~~~~~~~~~~~~^^^^^^^^^^^^^^^^^^^^^^^^^^^^^^
  File "<frozen importlib._bootstrap>", line 1387, in _gcd_import
  File "<frozen importlib._bootstrap>", line 1360, in _find_and_load
  File "<frozen importlib._bootstrap>", line 1331, in _find_and_load_unlocked
  File "<frozen importlib._bootstrap>", line 935, in _load_unlocked
  File "<frozen importlib._bootstrap_external>", line 1026, in exec_module
  File "<frozen importlib._bootstrap>", line 488, in _call_with_frames_removed
  File "D:\DOCNET\docnet-backend\config\urls.py", line 33, in <module>
    path('core/',include('core.urls')), #admin
                 ~~~~~~~^^^^^^^^^^^^^
  File "D:\DOCNET\docnet-backend\venv\Lib\site-packages\django\urls\conf.py", line 39, in include
    urlconf_module = import_module(urlconf_module)
  File "C:\Users\ASUS\AppData\Local\Programs\Python\Python313\Lib\importlib\__init__.py", line 88, in import_module
    return _bootstrap._gcd_import(name[level:], package, level)
           ~~~~~~~~~~~~~~~~~~~~~~^^^^^^^^^^^^^^^^^^^^^^^^^^^^^^
  File "<frozen importlib._bootstrap>", line 1387, in _gcd_import
  File "<frozen importlib._bootstrap>", line 1360, in _find_and_load
  File "<frozen importlib._bootstrap>", line 1331, in _find_and_load_unlocked
  File "<frozen importlib._bootstrap>", line 935, in _load_unlocked
  File "<frozen importlib._bootstrap_external>", line 1026, in exec_module
  File "<frozen importlib._bootstrap>", line 488, in _call_with_frames_removed
  File "D:\DOCNET\docnet-backend\core\urls.py", line 3, in <module>
    from .views import AdminPaymentHistoryAPIView,DoctorEarningsReportAPIView,AdminPaymentCSVExportView,AdminPaymentPDFExportView,DoctorReportsView,MarkReportAsReadView
ImportError: cannot import name 'ApproveWithdrawalView' from 'core.views' (D:\DOCNET\docnet-backend\core\views.py)

During handling of the above exception, another exception occurred:

Traceback (most recent call last):
  File "D:\DOCNET\docnet-backend\venv\Lib\site-packages\django\core\handlers\exception.py", line 55, in inner
    response = get_response(request)
  File "D:\DOCNET\docnet-backend\core\middleware.py", line 51, in __call__
    return self.get_response(request)
           ~~~~~~~~~~~~~~~~~^^^^^^^^^
  File "D:\DOCNET\docnet-backend\venv\Lib\site-packages\asgiref\sync.py", line 254, in __call__
    return call_result.result()
           ~~~~~~~~~~~~~~~~~~^^
  File "C:\Users\ASUS\AppData\Local\Programs\Python\Python313\Lib\concurrent\futures\_base.py", line 449, in result
    return self.__get_result()
           ~~~~~~~~~~~~~~~~~^^
  File "C:\Users\ASUS\AppData\Local\Programs\Python\Python313\Lib\concurrent\futures\_base.py", line 401, in __get_result
    raise self._exception
  File "D:\DOCNET\docnet-backend\venv\Lib\site-packages\asgiref\sync.py", line 331, in main_wrap
    result = await self.awaitable(*args, **kwargs)
             ^^^^^^^^^^^^^^^^^^^^^^^^^^^^^^^^^^^^^
  File "D:\DOCNET\docnet-backend\venv\Lib\site-packages\django\core\handlers\exception.py", line 44, in inner
    response = await sync_to_async(
               ^^^^^^^^^^^^^^^^^^^^
        response_for_exception, thread_sensitive=False
        ^^^^^^^^^^^^^^^^^^^^^^^^^^^^^^^^^^^^^^^^^^^^^^
    )(request, exc)
    ^^^^^^^^^^^^^^^
  File "D:\DOCNET\docnet-backend\venv\Lib\site-packages\asgiref\sync.py", line 468, in __call__
    ret = await asyncio.shield(exec_coro)
          ^^^^^^^^^^^^^^^^^^^^^^^^^^^^^^^
  File "C:\Users\ASUS\AppData\Local\Programs\Python\Python313\Lib\concurrent\futures\thread.py", line 59, in run
    result = self.fn(*self.args, **self.kwargs)
  File "D:\DOCNET\docnet-backend\venv\Lib\site-packages\asgiref\sync.py", line 520, in thread_handler
    return func(*args, **kwargs)
  File "D:\DOCNET\docnet-backend\venv\Lib\site-packages\django\core\handlers\exception.py", line 140, in response_for_exception
    response = handle_uncaught_exception(
        request, get_resolver(get_urlconf()), sys.exc_info()
    )
  File "D:\DOCNET\docnet-backend\venv\Lib\site-packages\django\core\handlers\exception.py", line 181, in handle_uncaught_exception
    return debug.technical_500_response(request, *exc_info)
           ~~~~~~~~~~~~~~~~~~~~~~~~~~~~^^^^^^^^^^^^^^^^^^^^
  File "D:\DOCNET\docnet-backend\venv\Lib\site-packages\django\views\debug.py", line 69, in technical_500_response
    html = reporter.get_traceback_html()
  File "D:\DOCNET\docnet-backend\venv\Lib\site-packages\django\views\debug.py", line 428, in get_traceback_html
    c = Context(self.get_traceback_data(), use_l10n=False)
                ~~~~~~~~~~~~~~~~~~~~~~~^^
  File "D:\DOCNET\docnet-backend\venv\Lib\site-packages\django\views\debug.py", line 411, in get_traceback_data
    c["raising_view_name"] = get_caller(self.request)
                             ~~~~~~~~~~^^^^^^^^^^^^^^
  File "D:\DOCNET\docnet-backend\venv\Lib\site-packages\django\views\debug.py", line 102, in get_caller
    resolver_match = resolve(request.path)
  File "D:\DOCNET\docnet-backend\venv\Lib\site-packages\django\urls\base.py", line 25, in resolve
    return get_resolver(urlconf).resolve(path)
           ~~~~~~~~~~~~~~~~~~~~~~~~~~~~~^^^^^^
  File "D:\DOCNET\docnet-backend\venv\Lib\site-packages\django\urls\resolvers.py", line 666, in resolve
    for pattern in self.url_patterns:
                   ^^^^^^^^^^^^^^^^^
  File "D:\DOCNET\docnet-backend\venv\Lib\site-packages\django\utils\functional.py", line 47, in __get__
    res = instance.__dict__[self.name] = self.func(instance)
                                         ~~~~~~~~~^^^^^^^^^^
  File "D:\DOCNET\docnet-backend\venv\Lib\site-packages\django\urls\resolvers.py", line 718, in url_patterns
    patterns = getattr(self.urlconf_module, "urlpatterns", self.urlconf_module)
                       ^^^^^^^^^^^^^^^^^^^
  File "D:\DOCNET\docnet-backend\venv\Lib\site-packages\django\utils\functional.py", line 47, in __get__
    res = instance.__dict__[self.name] = self.func(instance)
                                         ~~~~~~~~~^^^^^^^^^^
  File "D:\DOCNET\docnet-backend\venv\Lib\site-packages\django\urls\resolvers.py", line 711, in urlconf_module
    return import_module(self.urlconf_name)
  File "C:\Users\ASUS\AppData\Local\Programs\Python\Python313\Lib\importlib\__init__.py", line 88, in import_module
    return _bootstrap._gcd_import(name[level:], package, level)
           ~~~~~~~~~~~~~~~~~~~~~~^^^^^^^^^^^^^^^^^^^^^^^^^^^^^^
  File "<frozen importlib._bootstrap>", line 1387, in _gcd_import
  File "<frozen importlib._bootstrap>", line 1360, in _find_and_load
  File "<frozen importlib._bootstrap>", line 1331, in _find_and_load_unlocked
  File "<frozen importlib._bootstrap>", line 935, in _load_unlocked
  File "<frozen importlib._bootstrap_external>", line 1026, in exec_module
  File "<frozen importlib._bootstrap>", line 488, in _call_with_frames_removed
  File "D:\DOCNET\docnet-backend\config\urls.py", line 33, in <module>
    path('core/',include('core.urls')), #admin
                 ~~~~~~~^^^^^^^^^^^^^
  File "D:\DOCNET\docnet-backend\venv\Lib\site-packages\django\urls\conf.py", line 39, in include
    urlconf_module = import_module(urlconf_module)
  File "C:\Users\ASUS\AppData\Local\Programs\Python\Python313\Lib\importlib\__init__.py", line 88, in import_module
    return _bootstrap._gcd_import(name[level:], package, level)
           ~~~~~~~~~~~~~~~~~~~~~~^^^^^^^^^^^^^^^^^^^^^^^^^^^^^^
  File "<frozen importlib._bootstrap>", line 1387, in _gcd_import
  File "<frozen importlib._bootstrap>", line 1360, in _find_and_load
  File "<frozen importlib._bootstrap>", line 1331, in _find_and_load_unlocked
  File "<frozen importlib._bootstrap>", line 935, in _load_unlocked
  File "<frozen importlib._bootstrap_external>", line 1026, in exec_module
  File "<frozen importlib._bootstrap>", line 488, in _call_with_frames_removed
  File "D:\DOCNET\docnet-backend\core\urls.py", line 3, in <module>
    from .views import AdminPaymentHistoryAPIView,DoctorEarningsReportAPIView,AdminPaymentCSVExportView,AdminPaymentPDFExportView,DoctorReportsView,MarkReportAsReadView
ImportError: cannot import name 'ApproveWithdrawalView' from 'core.views' (D:\DOCNET\docnet-backend\core\views.py)

During handling of the above exception, another exception occurred:

Traceback (most recent call last):
  File "D:\DOCNET\docnet-backend\venv\Lib\site-packages\django\core\handlers\exception.py", line 55, in inner
    response = get_response(request)
  File "D:\DOCNET\docnet-backend\venv\Lib\site-packages\django\utils\deprecation.py", line 120, in __call__
    response = response or self.get_response(request)
                           ~~~~~~~~~~~~~~~~~^^^^^^^^^
  File "D:\DOCNET\docnet-backend\venv\Lib\site-packages\django\core\handlers\exception.py", line 57, in inner
    response = response_for_exception(request, exc)
  File "D:\DOCNET\docnet-backend\venv\Lib\site-packages\django\core\handlers\exception.py", line 140, in response_for_exception
    response = handle_uncaught_exception(
        request, get_resolver(get_urlconf()), sys.exc_info()
    )
  File "D:\DOCNET\docnet-backend\venv\Lib\site-packages\django\core\handlers\exception.py", line 181, in handle_uncaught_exception
    return debug.technical_500_response(request, *exc_info)
           ~~~~~~~~~~~~~~~~~~~~~~~~~~~~^^^^^^^^^^^^^^^^^^^^
  File "D:\DOCNET\docnet-backend\venv\Lib\site-packages\django\views\debug.py", line 69, in technical_500_response
    html = reporter.get_traceback_html()
  File "D:\DOCNET\docnet-backend\venv\Lib\site-packages\django\views\debug.py", line 428, in get_traceback_html
    c = Context(self.get_traceback_data(), use_l10n=False)
                ~~~~~~~~~~~~~~~~~~~~~~~^^
  File "D:\DOCNET\docnet-backend\venv\Lib\site-packages\django\views\debug.py", line 411, in get_traceback_data
    c["raising_view_name"] = get_caller(self.request)
                             ~~~~~~~~~~^^^^^^^^^^^^^^
  File "D:\DOCNET\docnet-backend\venv\Lib\site-packages\django\views\debug.py", line 102, in get_caller
    resolver_match = resolve(request.path)
  File "D:\DOCNET\docnet-backend\venv\Lib\site-packages\django\urls\base.py", line 25, in resolve
    return get_resolver(urlconf).resolve(path)
           ~~~~~~~~~~~~~~~~~~~~~~~~~~~~~^^^^^^
  File "D:\DOCNET\docnet-backend\venv\Lib\site-packages\django\urls\resolvers.py", line 666, in resolve
    for pattern in self.url_patterns:
                   ^^^^^^^^^^^^^^^^^
  File "D:\DOCNET\docnet-backend\venv\Lib\site-packages\django\utils\functional.py", line 47, in __get__
    res = instance.__dict__[self.name] = self.func(instance)
                                         ~~~~~~~~~^^^^^^^^^^
  File "D:\DOCNET\docnet-backend\venv\Lib\site-packages\django\urls\resolvers.py", line 718, in url_patterns
    patterns = getattr(self.urlconf_module, "urlpatterns", self.urlconf_module)
                       ^^^^^^^^^^^^^^^^^^^
  File "D:\DOCNET\docnet-backend\venv\Lib\site-packages\django\utils\functional.py", line 47, in __get__
    res = instance.__dict__[self.name] = self.func(instance)
                                         ~~~~~~~~~^^^^^^^^^^
  File "D:\DOCNET\docnet-backend\venv\Lib\site-packages\django\urls\resolvers.py", line 711, in urlconf_module
    return import_module(self.urlconf_name)
  File "C:\Users\ASUS\AppData\Local\Programs\Python\Python313\Lib\importlib\__init__.py", line 88, in import_module
    return _bootstrap._gcd_import(name[level:], package, level)
           ~~~~~~~~~~~~~~~~~~~~~~^^^^^^^^^^^^^^^^^^^^^^^^^^^^^^
  File "<frozen importlib._bootstrap>", line 1387, in _gcd_import
  File "<frozen importlib._bootstrap>", line 1360, in _find_and_load
  File "<frozen importlib._bootstrap>", line 1331, in _find_and_load_unlocked
  File "<frozen importlib._bootstrap>", line 935, in _load_unlocked
  File "<frozen importlib._bootstrap_external>", line 1026, in exec_module
  File "<frozen importlib._bootstrap>", line 488, in _call_with_frames_removed
  File "D:\DOCNET\docnet-backend\config\urls.py", line 33, in <module>
    path('core/',include('core.urls')), #admin
                 ~~~~~~~^^^^^^^^^^^^^
  File "D:\DOCNET\docnet-backend\venv\Lib\site-packages\django\urls\conf.py", line 39, in include
    urlconf_module = import_module(urlconf_module)
  File "C:\Users\ASUS\AppData\Local\Programs\Python\Python313\Lib\importlib\__init__.py", line 88, in import_module
    return _bootstrap._gcd_import(name[level:], package, level)
           ~~~~~~~~~~~~~~~~~~~~~~^^^^^^^^^^^^^^^^^^^^^^^^^^^^^^
  File "<frozen importlib._bootstrap>", line 1387, in _gcd_import
  File "<frozen importlib._bootstrap>", line 1360, in _find_and_load
  File "<frozen importlib._bootstrap>", line 1331, in _find_and_load_unlocked
  File "<frozen importlib._bootstrap>", line 935, in _load_unlocked
  File "<frozen importlib._bootstrap_external>", line 1026, in exec_module
  File "<frozen importlib._bootstrap>", line 488, in _call_with_frames_removed
  File "D:\DOCNET\docnet-backend\core\urls.py", line 3, in <module>
    from .views import AdminPaymentHistoryAPIView,DoctorEarningsReportAPIView,AdminPaymentCSVExportView,AdminPaymentPDFExportView,DoctorReportsView,MarkReportAsReadView
ImportError: cannot import name 'ApproveWithdrawalView' from 'core.views' (D:\DOCNET\docnet-backend\core\views.py)

During handling of the above exception, another exception occurred:

Traceback (most recent call last):
  File "D:\DOCNET\docnet-backend\venv\Lib\site-packages\django\core\handlers\exception.py", line 55, in inner
    response = get_response(request)
  File "D:\DOCNET\docnet-backend\venv\Lib\site-packages\django\utils\deprecation.py", line 120, in __call__
    response = response or self.get_response(request)
                           ~~~~~~~~~~~~~~~~~^^^^^^^^^
  File "D:\DOCNET\docnet-backend\venv\Lib\site-packages\django\core\handlers\exception.py", line 57, in inner
    response = response_for_exception(request, exc)
  File "D:\DOCNET\docnet-backend\venv\Lib\site-packages\django\core\handlers\exception.py", line 140, in response_for_exception
    response = handle_uncaught_exception(
        request, get_resolver(get_urlconf()), sys.exc_info()
    )
  File "D:\DOCNET\docnet-backend\venv\Lib\site-packages\django\core\handlers\exception.py", line 181, in handle_uncaught_exception
    return debug.technical_500_response(request, *exc_info)
           ~~~~~~~~~~~~~~~~~~~~~~~~~~~~^^^^^^^^^^^^^^^^^^^^
  File "D:\DOCNET\docnet-backend\venv\Lib\site-packages\django\views\debug.py", line 69, in technical_500_response
    html = reporter.get_traceback_html()
  File "D:\DOCNET\docnet-backend\venv\Lib\site-packages\django\views\debug.py", line 428, in get_traceback_html
    c = Context(self.get_traceback_data(), use_l10n=False)
                ~~~~~~~~~~~~~~~~~~~~~~~^^
  File "D:\DOCNET\docnet-backend\venv\Lib\site-packages\django\views\debug.py", line 411, in get_traceback_data
    c["raising_view_name"] = get_caller(self.request)
                             ~~~~~~~~~~^^^^^^^^^^^^^^
  File "D:\DOCNET\docnet-backend\venv\Lib\site-packages\django\views\debug.py", line 102, in get_caller
    resolver_match = resolve(request.path)
  File "D:\DOCNET\docnet-backend\venv\Lib\site-packages\django\urls\base.py", line 25, in resolve
    return get_resolver(urlconf).resolve(path)
           ~~~~~~~~~~~~~~~~~~~~~~~~~~~~~^^^^^^
  File "D:\DOCNET\docnet-backend\venv\Lib\site-packages\django\urls\resolvers.py", line 666, in resolve
    for pattern in self.url_patterns:
                   ^^^^^^^^^^^^^^^^^
  File "D:\DOCNET\docnet-backend\venv\Lib\site-packages\django\utils\functional.py", line 47, in __get__
    res = instance.__dict__[self.name] = self.func(instance)
                                         ~~~~~~~~~^^^^^^^^^^
  File "D:\DOCNET\docnet-backend\venv\Lib\site-packages\django\urls\resolvers.py", line 718, in url_patterns
    patterns = getattr(self.urlconf_module, "urlpatterns", self.urlconf_module)
                       ^^^^^^^^^^^^^^^^^^^
  File "D:\DOCNET\docnet-backend\venv\Lib\site-packages\django\utils\functional.py", line 47, in __get__
    res = instance.__dict__[self.name] = self.func(instance)
                                         ~~~~~~~~~^^^^^^^^^^
  File "D:\DOCNET\docnet-backend\venv\Lib\site-packages\django\urls\resolvers.py", line 711, in urlconf_module
    return import_module(self.urlconf_name)
  File "C:\Users\ASUS\AppData\Local\Programs\Python\Python313\Lib\importlib\__init__.py", line 88, in import_module
    return _bootstrap._gcd_import(name[level:], package, level)
           ~~~~~~~~~~~~~~~~~~~~~~^^^^^^^^^^^^^^^^^^^^^^^^^^^^^^
  File "<frozen importlib._bootstrap>", line 1387, in _gcd_import
  File "<frozen importlib._bootstrap>", line 1360, in _find_and_load
  File "<frozen importlib._bootstrap>", line 1331, in _find_and_load_unlocked
  File "<frozen importlib._bootstrap>", line 935, in _load_unlocked
  File "<frozen importlib._bootstrap_external>", line 1026, in exec_module
  File "<frozen importlib._bootstrap>", line 488, in _call_with_frames_removed
  File "D:\DOCNET\docnet-backend\config\urls.py", line 33, in <module>
    path('core/',include('core.urls')), #admin
                 ~~~~~~~^^^^^^^^^^^^^
  File "D:\DOCNET\docnet-backend\venv\Lib\site-packages\django\urls\conf.py", line 39, in include
    urlconf_module = import_module(urlconf_module)
  File "C:\Users\ASUS\AppData\Local\Programs\Python\Python313\Lib\importlib\__init__.py", line 88, in import_module
    return _bootstrap._gcd_import(name[level:], package, level)
           ~~~~~~~~~~~~~~~~~~~~~~^^^^^^^^^^^^^^^^^^^^^^^^^^^^^^
  File "<frozen importlib._bootstrap>", line 1387, in _gcd_import
  File "<frozen importlib._bootstrap>", line 1360, in _find_and_load
  File "<frozen importlib._bootstrap>", line 1331, in _find_and_load_unlocked
  File "<frozen importlib._bootstrap>", line 935, in _load_unlocked
  File "<frozen importlib._bootstrap_external>", line 1026, in exec_module
  File "<frozen importlib._bootstrap>", line 488, in _call_with_frames_removed
  File "D:\DOCNET\docnet-backend\core\urls.py", line 3, in <module>
    from .views import AdminPaymentHistoryAPIView,DoctorEarningsReportAPIView,AdminPaymentCSVExportView,AdminPaymentPDFExportView,DoctorReportsView,MarkReportAsReadView
ImportError: cannot import name 'ApproveWithdrawalView' from 'core.views' (D:\DOCNET\docnet-backend\core\views.py)
WARNING 2025-07-19 10:50:20,526 log 10512 21416 Not Found: /static/admin/css/dashboard.css
WARNING 2025-07-19 10:50:20,528 log 10512 4112 Not Found: /static/admin/css/base.css
WARNING 2025-07-19 10:50:20,528 log 10512 12228 Not Found: /static/admin/css/nav_sidebar.css
WARNING 2025-07-19 10:50:20,530 log 10512 7948 Not Found: /static/admin/css/responsive.css
WARNING 2025-07-19 10:50:20,530 log 10512 15280 Not Found: /static/admin/js/theme.js
WARNING 2025-07-19 10:50:20,530 log 10512 20828 Not Found: /static/admin/css/dark_mode.css
WARNING 2025-07-19 10:50:20,571 log 10512 15280 Not Found: /static/admin/js/nav_sidebar.js
WARNING 2025-07-19 10:50:20,572 log 10512 20828 Not Found: /static/admin/css/nav_sidebar.css
WARNING 2025-07-19 10:50:20,572 log 10512 21416 Not Found: /static/admin/css/responsive.css
WARNING 2025-07-19 10:50:20,573 log 10512 4112 Not Found: /static/admin/css/dashboard.css
WARNING 2025-07-19 10:50:20,639 log 10512 12228 Not Found: /favicon.ico
WARNING 2025-07-19 10:50:42,159 log 10512 12228 Not Found: /static/admin/css/nav_sidebar.css
WARNING 2025-07-19 10:50:42,159 log 10512 7948 Not Found: /static/admin/js/theme.js
WARNING 2025-07-19 10:50:42,160 log 10512 15280 Not Found: /static/admin/css/base.css
WARNING 2025-07-19 10:50:42,160 log 10512 21416 Not Found: /static/admin/css/changelists.css
WARNING 2025-07-19 10:50:42,160 log 10512 4112 Not Found: /static/admin/css/dark_mode.css
WARNING 2025-07-19 10:50:42,196 log 10512 4112 Not Found: /static/admin/js/jquery.init.js
WARNING 2025-07-19 10:50:42,196 log 10512 7948 Not Found: /static/admin/css/responsive.css
WARNING 2025-07-19 10:50:42,197 log 10512 12228 Not Found: /static/admin/js/vendor/jquery/jquery.js
WARNING 2025-07-19 10:50:42,198 log 10512 21416 Not Found: /static/admin/js/admin/RelatedObjectLookups.js
WARNING 2025-07-19 10:50:42,198 log 10512 20828 Not Found: /static/admin/js/core.js
WARNING 2025-07-19 10:50:42,237 log 10512 20828 Not Found: /static/admin/css/nav_sidebar.css
WARNING 2025-07-19 10:50:42,237 log 10512 15280 Not Found: /static/admin/js/actions.js
WARNING 2025-07-19 10:50:42,238 log 10512 12228 Not Found: /static/admin/js/prepopulate.js
WARNING 2025-07-19 10:50:42,238 log 10512 7948 Not Found: /static/admin/css/changelists.css
WARNING 2025-07-19 10:50:42,238 log 10512 4112 Not Found: /static/admin/js/urlify.js
WARNING 2025-07-19 10:50:42,257 log 10512 15280 Not Found: /static/admin/js/vendor/xregexp/xregexp.js
WARNING 2025-07-19 10:50:42,258 log 10512 12228 Not Found: /static/admin/img/search.svg
WARNING 2025-07-19 10:50:42,280 log 10512 20828 Not Found: /static/admin/js/nav_sidebar.js
WARNING 2025-07-19 10:50:42,280 log 10512 15280 Not Found: /static/admin/js/filters.js
WARNING 2025-07-19 10:50:42,280 log 10512 12228 Not Found: /static/admin/css/responsive.css
ERROR 2025-07-19 10:57:18,019 log 21476 10788 Internal Server Error: /doctor/withdrawal/request/
Traceback (most recent call last):
  File "D:\DOCNET\docnet-backend\venv\Lib\site-packages\asgiref\sync.py", line 518, in thread_handler
    raise exc_info[1]
  File "D:\DOCNET\docnet-backend\venv\Lib\site-packages\django\core\handlers\exception.py", line 42, in inner
    response = await get_response(request)
               ^^^^^^^^^^^^^^^^^^^^^^^^^^^
  File "D:\DOCNET\docnet-backend\venv\Lib\site-packages\asgiref\sync.py", line 518, in thread_handler
    raise exc_info[1]
  File "D:\DOCNET\docnet-backend\venv\Lib\site-packages\django\core\handlers\base.py", line 253, in _get_response_async
    response = await wrapped_callback(
               ^^^^^^^^^^^^^^^^^^^^^^^
        request, *callback_args, **callback_kwargs
        ^^^^^^^^^^^^^^^^^^^^^^^^^^^^^^^^^^^^^^^^^^
    )
    ^
  File "D:\DOCNET\docnet-backend\venv\Lib\site-packages\asgiref\sync.py", line 468, in __call__
    ret = await asyncio.shield(exec_coro)
          ^^^^^^^^^^^^^^^^^^^^^^^^^^^^^^^
  File "D:\DOCNET\docnet-backend\venv\Lib\site-packages\asgiref\current_thread_executor.py", line 40, in run
    result = self.fn(*self.args, **self.kwargs)
  File "D:\DOCNET\docnet-backend\venv\Lib\site-packages\asgiref\sync.py", line 522, in thread_handler
    return func(*args, **kwargs)
  File "D:\DOCNET\docnet-backend\venv\Lib\site-packages\django\views\decorators\csrf.py", line 65, in _view_wrapper
    return view_func(request, *args, **kwargs)
  File "D:\DOCNET\docnet-backend\venv\Lib\site-packages\django\views\generic\base.py", line 104, in view
    return self.dispatch(request, *args, **kwargs)
           ~~~~~~~~~~~~~^^^^^^^^^^^^^^^^^^^^^^^^^^
  File "D:\DOCNET\docnet-backend\venv\Lib\site-packages\rest_framework\views.py", line 515, in dispatch
    response = self.handle_exception(exc)
  File "D:\DOCNET\docnet-backend\venv\Lib\site-packages\rest_framework\views.py", line 475, in handle_exception
    self.raise_uncaught_exception(exc)
    ~~~~~~~~~~~~~~~~~~~~~~~~~~~~~^^^^^
  File "D:\DOCNET\docnet-backend\venv\Lib\site-packages\rest_framework\views.py", line 486, in raise_uncaught_exception
    raise exc
  File "D:\DOCNET\docnet-backend\venv\Lib\site-packages\rest_framework\views.py", line 512, in dispatch
    response = handler(request, *args, **kwargs)
  File "D:\DOCNET\docnet-backend\doctor\views.py", line 1120, in post
    'transaction': serializer.data
                   ^^^^^^^^^^^^^^^
  File "D:\DOCNET\docnet-backend\venv\Lib\site-packages\rest_framework\serializers.py", line 573, in data
    ret = super().data
          ^^^^^^^^^^^^
  File "D:\DOCNET\docnet-backend\venv\Lib\site-packages\rest_framework\serializers.py", line 251, in data
    self._data = self.to_representation(self.instance)
                 ~~~~~~~~~~~~~~~~~~~~~~^^^^^^^^^^^^^^^
  File "D:\DOCNET\docnet-backend\venv\Lib\site-packages\rest_framework\serializers.py", line 540, in to_representation
    ret[field.field_name] = field.to_representation(attribute)
                            ~~~~~~~~~~~~~~~~~~~~~~~^^^^^^^^^^^
  File "D:\DOCNET\docnet-backend\venv\Lib\site-packages\rest_framework\fields.py", line 1870, in to_representation
    return method(value)
  File "D:\DOCNET\docnet-backend\doctor\serializers.py", line 593, in get_new_balance
    return wallet.balance
           ^^^^^^^^^^^^^^
AttributeError: 'RelatedManager' object has no attribute 'balance'
ERROR 2025-07-19 11:04:40,650 log 21476 10788 Internal Server Error: /doctor/withdrawal/request/
Traceback (most recent call last):
  File "D:\DOCNET\docnet-backend\venv\Lib\site-packages\asgiref\sync.py", line 518, in thread_handler
    raise exc_info[1]
  File "D:\DOCNET\docnet-backend\venv\Lib\site-packages\django\core\handlers\exception.py", line 42, in inner
    response = await get_response(request)
               ^^^^^^^^^^^^^^^^^^^^^^^^^^^
  File "D:\DOCNET\docnet-backend\venv\Lib\site-packages\asgiref\sync.py", line 518, in thread_handler
    raise exc_info[1]
  File "D:\DOCNET\docnet-backend\venv\Lib\site-packages\django\core\handlers\base.py", line 253, in _get_response_async
    response = await wrapped_callback(
               ^^^^^^^^^^^^^^^^^^^^^^^
        request, *callback_args, **callback_kwargs
        ^^^^^^^^^^^^^^^^^^^^^^^^^^^^^^^^^^^^^^^^^^
    )
    ^
  File "D:\DOCNET\docnet-backend\venv\Lib\site-packages\asgiref\sync.py", line 468, in __call__
    ret = await asyncio.shield(exec_coro)
          ^^^^^^^^^^^^^^^^^^^^^^^^^^^^^^^
  File "D:\DOCNET\docnet-backend\venv\Lib\site-packages\asgiref\current_thread_executor.py", line 40, in run
    result = self.fn(*self.args, **self.kwargs)
  File "D:\DOCNET\docnet-backend\venv\Lib\site-packages\asgiref\sync.py", line 522, in thread_handler
    return func(*args, **kwargs)
  File "D:\DOCNET\docnet-backend\venv\Lib\site-packages\django\views\decorators\csrf.py", line 65, in _view_wrapper
    return view_func(request, *args, **kwargs)
  File "D:\DOCNET\docnet-backend\venv\Lib\site-packages\django\views\generic\base.py", line 104, in view
    return self.dispatch(request, *args, **kwargs)
           ~~~~~~~~~~~~~^^^^^^^^^^^^^^^^^^^^^^^^^^
  File "D:\DOCNET\docnet-backend\venv\Lib\site-packages\rest_framework\views.py", line 515, in dispatch
    response = self.handle_exception(exc)
  File "D:\DOCNET\docnet-backend\venv\Lib\site-packages\rest_framework\views.py", line 475, in handle_exception
    self.raise_uncaught_exception(exc)
    ~~~~~~~~~~~~~~~~~~~~~~~~~~~~~^^^^^
  File "D:\DOCNET\docnet-backend\venv\Lib\site-packages\rest_framework\views.py", line 486, in raise_uncaught_exception
    raise exc
  File "D:\DOCNET\docnet-backend\venv\Lib\site-packages\rest_framework\views.py", line 512, in dispatch
    response = handler(request, *args, **kwargs)
  File "D:\DOCNET\docnet-backend\doctor\views.py", line 1120, in post
    'transaction': serializer.data
                   ^^^^^^^^^^^^^^^
  File "D:\DOCNET\docnet-backend\venv\Lib\site-packages\rest_framework\serializers.py", line 573, in data
    ret = super().data
          ^^^^^^^^^^^^
  File "D:\DOCNET\docnet-backend\venv\Lib\site-packages\rest_framework\serializers.py", line 251, in data
    self._data = self.to_representation(self.instance)
                 ~~~~~~~~~~~~~~~~~~~~~~^^^^^^^^^^^^^^^
  File "D:\DOCNET\docnet-backend\venv\Lib\site-packages\rest_framework\serializers.py", line 540, in to_representation
    ret[field.field_name] = field.to_representation(attribute)
                            ~~~~~~~~~~~~~~~~~~~~~~~^^^^^^^^^^^
  File "D:\DOCNET\docnet-backend\venv\Lib\site-packages\rest_framework\fields.py", line 1870, in to_representation
    return method(value)
  File "D:\DOCNET\docnet-backend\doctor\serializers.py", line 593, in get_new_balance
    return wallet.balance
           ^^^^^^^^^^^^^^
AttributeError: 'RelatedManager' object has no attribute 'balance'
WARNING 2025-07-19 11:07:17,487 log 13012 17064 Not Found: /static/admin/css/base.css
WARNING 2025-07-19 11:07:17,488 log 13012 15116 Not Found: /static/admin/css/dark_mode.css
WARNING 2025-07-19 11:07:17,489 log 13012 9420 Not Found: /static/admin/css/nav_sidebar.css
WARNING 2025-07-19 11:07:17,489 log 13012 17064 Not Found: /static/admin/js/theme.js
WARNING 2025-07-19 11:07:17,491 log 13012 15116 Not Found: /static/admin/css/changelists.css
WARNING 2025-07-19 11:07:17,531 log 13012 12588 Not Found: /static/admin/js/core.js
WARNING 2025-07-19 11:07:17,531 log 13012 15116 Not Found: /static/admin/css/responsive.css
WARNING 2025-07-19 11:07:17,531 log 13012 17064 Not Found: /static/admin/js/admin/RelatedObjectLookups.js
WARNING 2025-07-19 11:07:17,531 log 13012 19008 Not Found: /static/admin/js/jquery.init.js
WARNING 2025-07-19 11:07:17,531 log 13012 9420 Not Found: /static/admin/js/vendor/jquery/jquery.js
WARNING 2025-07-19 11:07:17,570 log 13012 12588 Not Found: /static/admin/css/nav_sidebar.css
WARNING 2025-07-19 11:07:17,570 log 13012 15116 Not Found: /static/admin/js/actions.js
WARNING 2025-07-19 11:07:17,571 log 13012 17064 Not Found: /static/admin/css/changelists.css
WARNING 2025-07-19 11:07:17,571 log 13012 9420 Not Found: /static/admin/js/urlify.js
WARNING 2025-07-19 11:07:17,571 log 13012 9180 Not Found: /static/admin/js/prepopulate.js
WARNING 2025-07-19 11:07:17,581 log 13012 19008 Not Found: /static/admin/js/vendor/xregexp/xregexp.js
WARNING 2025-07-19 11:07:17,591 log 13012 15116 Not Found: /static/admin/img/search.svg
WARNING 2025-07-19 11:07:17,604 log 13012 19008 Not Found: /static/admin/js/nav_sidebar.js
WARNING 2025-07-19 11:07:17,605 log 13012 12588 Not Found: /static/admin/js/filters.js
WARNING 2025-07-19 11:07:17,605 log 13012 15116 Not Found: /static/admin/css/responsive.css
WARNING 2025-07-19 11:07:21,880 log 13012 15116 Not Found: /static/admin/js/theme.js
WARNING 2025-07-19 11:07:21,880 log 13012 9180 Not Found: /static/admin/css/base.css
WARNING 2025-07-19 11:07:21,880 log 13012 9420 Not Found: /static/admin/css/nav_sidebar.css
WARNING 2025-07-19 11:07:21,881 log 13012 17064 Not Found: /static/admin/css/dark_mode.css
WARNING 2025-07-19 11:07:21,882 log 13012 19008 Not Found: /static/admin/css/changelists.css
WARNING 2025-07-19 11:07:21,916 log 13012 19008 Not Found: /static/admin/css/responsive.css
WARNING 2025-07-19 11:07:21,917 log 13012 12588 Not Found: /static/admin/css/nav_sidebar.css
WARNING 2025-07-19 11:07:21,918 log 13012 15116 Not Found: /static/admin/js/vendor/jquery/jquery.js
WARNING 2025-07-19 11:07:21,919 log 13012 17064 Not Found: /static/admin/js/jquery.init.js
WARNING 2025-07-19 11:07:21,921 log 13012 9180 Not Found: /static/admin/js/core.js
WARNING 2025-07-19 11:07:21,951 log 13012 9180 Not Found: /static/admin/js/admin/RelatedObjectLookups.js
WARNING 2025-07-19 11:07:21,954 log 13012 9420 Not Found: /static/admin/js/urlify.js
WARNING 2025-07-19 11:07:21,955 log 13012 19008 Not Found: /static/admin/js/actions.js
WARNING 2025-07-19 11:07:21,960 log 13012 15116 Not Found: /static/admin/js/prepopulate.js
WARNING 2025-07-19 11:07:21,964 log 13012 17064 Not Found: /static/admin/js/vendor/xregexp/xregexp.js
WARNING 2025-07-19 11:07:21,966 log 13012 9180 Not Found: /static/admin/img/search.svg
WARNING 2025-07-19 11:07:21,986 log 13012 17064 Not Found: /static/admin/js/filters.js
WARNING 2025-07-19 11:07:21,986 log 13012 15116 Not Found: /static/admin/js/nav_sidebar.js
WARNING 2025-07-19 11:07:21,986 log 13012 9180 Not Found: /static/admin/css/responsive.css
WARNING 2025-07-19 11:12:29,284 log 13012 19008 Not Found: /core/withdrawal-requests/
WARNING 2025-07-19 11:12:31,146 log 13012 17064 Not Found: /core/withdrawal-requests/
WARNING 2025-07-19 11:20:12,464 log 13012 9180 Not Found: /core/withdrawal-requests/
WARNING 2025-07-19 11:20:12,529 log 13012 19008 Not Found: /core/withdrawal-requests/
WARNING 2025-07-19 11:20:18,039 log 13012 17064 Not Found: /core/withdrawal-requests/
WARNING 2025-07-19 11:20:18,185 log 13012 9180 Not Found: /core/withdrawal-requests/
WARNING 2025-07-19 11:36:27,613 log 16408 13360 Bad Request: /core/withdrawal-requests/7/approve/
WARNING 2025-07-19 11:37:56,082 log 16408 13360 Bad Request: /core/withdrawal-requests/6/approve/
WARNING 2025-07-19 11:38:38,897 log 16408 13360 Bad Request: /core/withdrawal-requests/5/approve/
WARNING 2025-07-19 12:05:27,485 log 13340 19652 Bad Request: /core/withdrawal-requests/4/approve/
WARNING 2025-07-19 12:05:43,201 log 13340 19652 Bad Request: /core/withdrawal-requests/2/approve/
WARNING 2025-07-19 12:11:46,812 log 1452 6744 Bad Request: /core/withdrawal-requests/8/approve/
WARNING 2025-07-19 12:15:43,799 log 18636 9072 Bad Request: /core/withdrawal-requests/9/approve/
WARNING 2025-07-19 12:22:58,936 log 16160 19144 Bad Request: /core/withdrawal-requests/10/approve/
ERROR 2025-07-19 12:28:13,621 log 11196 14328 Internal Server Error: /core/withdrawal-requests/11/approve/
Traceback (most recent call last):
  File "D:\DOCNET\docnet-backend\venv\Lib\site-packages\asgiref\sync.py", line 518, in thread_handler
    raise exc_info[1]
  File "D:\DOCNET\docnet-backend\venv\Lib\site-packages\django\core\handlers\exception.py", line 42, in inner
    response = await get_response(request)
               ^^^^^^^^^^^^^^^^^^^^^^^^^^^
  File "D:\DOCNET\docnet-backend\venv\Lib\site-packages\asgiref\sync.py", line 518, in thread_handler
    raise exc_info[1]
  File "D:\DOCNET\docnet-backend\venv\Lib\site-packages\django\core\handlers\base.py", line 253, in _get_response_async
    response = await wrapped_callback(
               ^^^^^^^^^^^^^^^^^^^^^^^
        request, *callback_args, **callback_kwargs
        ^^^^^^^^^^^^^^^^^^^^^^^^^^^^^^^^^^^^^^^^^^
    )
    ^
  File "D:\DOCNET\docnet-backend\venv\Lib\site-packages\asgiref\sync.py", line 468, in __call__
    ret = await asyncio.shield(exec_coro)
          ^^^^^^^^^^^^^^^^^^^^^^^^^^^^^^^
  File "D:\DOCNET\docnet-backend\venv\Lib\site-packages\asgiref\current_thread_executor.py", line 40, in run
    result = self.fn(*self.args, **self.kwargs)
  File "D:\DOCNET\docnet-backend\venv\Lib\site-packages\asgiref\sync.py", line 522, in thread_handler
    return func(*args, **kwargs)
  File "D:\DOCNET\docnet-backend\venv\Lib\site-packages\django\views\decorators\csrf.py", line 65, in _view_wrapper
    return view_func(request, *args, **kwargs)
  File "D:\DOCNET\docnet-backend\venv\Lib\site-packages\django\views\generic\base.py", line 104, in view
    return self.dispatch(request, *args, **kwargs)
           ~~~~~~~~~~~~~^^^^^^^^^^^^^^^^^^^^^^^^^^
  File "D:\DOCNET\docnet-backend\venv\Lib\site-packages\rest_framework\views.py", line 515, in dispatch
    response = self.handle_exception(exc)
  File "D:\DOCNET\docnet-backend\venv\Lib\site-packages\rest_framework\views.py", line 475, in handle_exception
    self.raise_uncaught_exception(exc)
    ~~~~~~~~~~~~~~~~~~~~~~~~~~~~~^^^^^
  File "D:\DOCNET\docnet-backend\venv\Lib\site-packages\rest_framework\views.py", line 486, in raise_uncaught_exception
    raise exc
  File "D:\DOCNET\docnet-backend\venv\Lib\site-packages\rest_framework\views.py", line 512, in dispatch
    response = handler(request, *args, **kwargs)
  File "D:\DOCNET\docnet-backend\core\views.py", line 558, in post
    payout_result = make_cashfree_payout(
        beneficiary_id=doctor.beneficiary_id,
        amount=withdrawal.amount,
        remarks=request.data.get("remarks", "Doctor Withdrawal")
    )
TypeError: make_cashfree_payout() missing 1 required positional argument: 'token'
ERROR 2025-07-19 12:34:38,399 log 19680 15280 Internal Server Error: /core/withdrawal-requests/11/approve/
Traceback (most recent call last):
  File "D:\DOCNET\docnet-backend\venv\Lib\site-packages\asgiref\sync.py", line 518, in thread_handler
    raise exc_info[1]
  File "D:\DOCNET\docnet-backend\venv\Lib\site-packages\django\core\handlers\exception.py", line 42, in inner
    response = await get_response(request)
               ^^^^^^^^^^^^^^^^^^^^^^^^^^^
  File "D:\DOCNET\docnet-backend\venv\Lib\site-packages\asgiref\sync.py", line 518, in thread_handler
    raise exc_info[1]
  File "D:\DOCNET\docnet-backend\venv\Lib\site-packages\django\core\handlers\base.py", line 253, in _get_response_async
    response = await wrapped_callback(
               ^^^^^^^^^^^^^^^^^^^^^^^
        request, *callback_args, **callback_kwargs
        ^^^^^^^^^^^^^^^^^^^^^^^^^^^^^^^^^^^^^^^^^^
    )
    ^
  File "D:\DOCNET\docnet-backend\venv\Lib\site-packages\asgiref\sync.py", line 468, in __call__
    ret = await asyncio.shield(exec_coro)
          ^^^^^^^^^^^^^^^^^^^^^^^^^^^^^^^
  File "D:\DOCNET\docnet-backend\venv\Lib\site-packages\asgiref\current_thread_executor.py", line 40, in run
    result = self.fn(*self.args, **self.kwargs)
  File "D:\DOCNET\docnet-backend\venv\Lib\site-packages\asgiref\sync.py", line 522, in thread_handler
    return func(*args, **kwargs)
  File "D:\DOCNET\docnet-backend\venv\Lib\site-packages\django\views\decorators\csrf.py", line 65, in _view_wrapper
    return view_func(request, *args, **kwargs)
  File "D:\DOCNET\docnet-backend\venv\Lib\site-packages\django\views\generic\base.py", line 104, in view
    return self.dispatch(request, *args, **kwargs)
           ~~~~~~~~~~~~~^^^^^^^^^^^^^^^^^^^^^^^^^^
  File "D:\DOCNET\docnet-backend\venv\Lib\site-packages\rest_framework\views.py", line 515, in dispatch
    response = self.handle_exception(exc)
  File "D:\DOCNET\docnet-backend\venv\Lib\site-packages\rest_framework\views.py", line 475, in handle_exception
    self.raise_uncaught_exception(exc)
    ~~~~~~~~~~~~~~~~~~~~~~~~~~~~~^^^^^
  File "D:\DOCNET\docnet-backend\venv\Lib\site-packages\rest_framework\views.py", line 486, in raise_uncaught_exception
    raise exc
  File "D:\DOCNET\docnet-backend\venv\Lib\site-packages\rest_framework\views.py", line 512, in dispatch
    response = handler(request, *args, **kwargs)
  File "D:\DOCNET\docnet-backend\core\views.py", line 535, in post
    token = get_cashfree_token()
            ^^^^^^^^^^^^^^^^^^
NameError: name 'get_cashfree_token' is not defined
WARNING 2025-07-19 12:36:30,396 log 7336 1592 Unauthorized: /core/withdrawal-requests/11/approve/
WARNING 2025-07-19 12:38:11,915 log 2308 7600 Unauthorized: /core/withdrawal-requests/11/approve/
WARNING 2025-07-19 12:45:47,750 log 16956 10104 Unauthorized: /core/withdrawal-requests/11/approve/
WARNING 2025-07-19 12:48:57,723 log 16956 10104 Unauthorized: /core/withdrawal-requests/11/approve/
WARNING 2025-07-19 12:49:05,172 log 16956 10104 Unauthorized: /core/withdrawal-requests/11/approve/
WARNING 2025-07-19 12:49:34,145 log 16956 10104 Unauthorized: /core/withdrawal-requests/2/approve/
WARNING 2025-07-19 15:17:01,541 log 16956 10104 Unauthorized: /core/withdrawal-requests/12/approve/
WARNING 2025-07-19 15:21:45,561 log 16956 10104 Unauthorized: /core/withdrawal-requests/12/approve/
WARNING 2025-07-19 15:23:50,893 log 18172 2920 Unauthorized: /core/withdrawal-requests/12/approve/
WARNING 2025-07-19 15:29:34,180 log 18172 2920 Unauthorized: /core/withdrawal-requests/12/approve/
WARNING 2025-07-19 15:37:49,672 log 18172 2920 Unauthorized: /core/withdrawal-requests/12/approve/
WARNING 2025-07-19 15:38:07,089 log 18172 2920 Unauthorized: /core/withdrawal-requests/12/approve/
WARNING 2025-07-19 15:38:28,409 log 18172 2920 Unauthorized: /core/withdrawal-requests/12/approve/
WARNING 2025-07-19 15:39:02,749 log 18172 2920 Unauthorized: /core/withdrawal-requests/12/approve/
WARNING 2025-07-19 15:39:14,868 log 18172 2920 Unauthorized: /core/withdrawal-requests/12/approve/
WARNING 2025-07-19 15:54:57,621 log 11820 15516 Unauthorized: /core/withdrawal-requests/12/approve/
WARNING 2025-07-19 15:56:35,466 log 22428 19100 Unauthorized: /core/withdrawal-requests/12/approve/
WARNING 2025-07-19 16:10:22,486 log 22428 19100 Unauthorized: /core/withdrawal-requests/12/approve/
WARNING 2025-07-19 16:19:14,442 log 22428 19100 Unauthorized: /core/withdrawal-requests/12/approve/
WARNING 2025-07-19 16:22:04,707 log 22428 19100 Unauthorized: /core/withdrawal-requests/12/approve/
WARNING 2025-07-19 18:43:29,684 log 9060 7224 Forbidden: /api/user-notifications/
WARNING 2025-07-19 18:43:29,695 log 9060 7224 Forbidden: /api/user-notifications/
WARNING 2025-07-19 18:43:30,057 log 9060 7224 Bad Request: /api/token/refresh/
WARNING 2025-07-19 18:43:30,057 log 9060 3104 Bad Request: /api/token/refresh/
WARNING 2025-07-19 18:44:10,142 log 9060 3104 Unauthorized: /core/admin-login/
WARNING 2025-07-19 18:44:54,577 log 9060 3104 Not Found: /core/withdrawal-requests/
WARNING 2025-07-19 18:44:54,627 log 9060 3104 Not Found: /core/withdrawal-requests/
WARNING 2025-07-19 18:44:59,865 log 9060 3104 Not Found: /core/withdrawal-requests/
WARNING 2025-07-19 18:45:00,023 log 9060 3104 Not Found: /core/withdrawal-requests/
WARNING 2025-07-19 18:45:02,431 log 9060 3104 Not Found: /core/withdrawal-requests/
WARNING 2025-07-19 18:45:02,484 log 9060 3104 Not Found: /core/withdrawal-requests/
WARNING 2025-07-19 18:45:07,950 log 9060 3104 Not Found: /core/withdrawal-requests/
WARNING 2025-07-19 18:45:08,012 log 9060 3104 Not Found: /core/withdrawal-requests/
WARNING 2025-07-19 19:12:07,994 log 7136 9288 Not Found: /core/withdrawal-requests/
WARNING 2025-07-19 19:12:08,056 log 7136 9288 Not Found: /core/withdrawal-requests/
WARNING 2025-07-19 19:12:12,600 log 7136 9288 Not Found: /core/withdrawal-requests/
WARNING 2025-07-19 19:12:12,649 log 7136 9288 Not Found: /core/withdrawal-requests/
WARNING 2025-07-19 19:13:31,495 log 16588 10672 Not Found: /core/withdrawal-requests/
WARNING 2025-07-19 19:13:31,570 log 16588 10672 Not Found: /core/withdrawal-requests/
WARNING 2025-07-19 19:13:40,931 log 16588 10672 Not Found: /core/withdrawal-requests/
WARNING 2025-07-19 19:13:41,007 log 16588 10672 Not Found: /core/withdrawal-requests/
ERROR 2025-07-19 19:19:48,061 log 18072 3732 Internal Server Error: /doctor/doctor-analytics/
Traceback (most recent call last):
  File "D:\DOCNET\docnet-backend\venv\Lib\site-packages\asgiref\sync.py", line 518, in thread_handler
    raise exc_info[1]
  File "D:\DOCNET\docnet-backend\venv\Lib\site-packages\django\core\handlers\exception.py", line 42, in inner
    response = await get_response(request)
               ^^^^^^^^^^^^^^^^^^^^^^^^^^^
  File "D:\DOCNET\docnet-backend\venv\Lib\site-packages\asgiref\sync.py", line 518, in thread_handler
    raise exc_info[1]
  File "D:\DOCNET\docnet-backend\venv\Lib\site-packages\django\core\handlers\base.py", line 253, in _get_response_async
    response = await wrapped_callback(
               ^^^^^^^^^^^^^^^^^^^^^^^
        request, *callback_args, **callback_kwargs
        ^^^^^^^^^^^^^^^^^^^^^^^^^^^^^^^^^^^^^^^^^^
    )
    ^
  File "D:\DOCNET\docnet-backend\venv\Lib\site-packages\asgiref\sync.py", line 468, in __call__
    ret = await asyncio.shield(exec_coro)
          ^^^^^^^^^^^^^^^^^^^^^^^^^^^^^^^
  File "D:\DOCNET\docnet-backend\venv\Lib\site-packages\asgiref\current_thread_executor.py", line 40, in run
    result = self.fn(*self.args, **self.kwargs)
  File "D:\DOCNET\docnet-backend\venv\Lib\site-packages\asgiref\sync.py", line 522, in thread_handler
    return func(*args, **kwargs)
  File "D:\DOCNET\docnet-backend\venv\Lib\site-packages\django\views\decorators\csrf.py", line 65, in _view_wrapper
    return view_func(request, *args, **kwargs)
  File "D:\DOCNET\docnet-backend\venv\Lib\site-packages\django\views\generic\base.py", line 104, in view
    return self.dispatch(request, *args, **kwargs)
           ~~~~~~~~~~~~~^^^^^^^^^^^^^^^^^^^^^^^^^^
  File "D:\DOCNET\docnet-backend\venv\Lib\site-packages\rest_framework\views.py", line 515, in dispatch
    response = self.handle_exception(exc)
  File "D:\DOCNET\docnet-backend\venv\Lib\site-packages\rest_framework\views.py", line 475, in handle_exception
    self.raise_uncaught_exception(exc)
    ~~~~~~~~~~~~~~~~~~~~~~~~~~~~~^^^^^
  File "D:\DOCNET\docnet-backend\venv\Lib\site-packages\rest_framework\views.py", line 486, in raise_uncaught_exception
    raise exc
  File "D:\DOCNET\docnet-backend\venv\Lib\site-packages\rest_framework\views.py", line 512, in dispatch
    response = handler(request, *args, **kwargs)
  File "D:\DOCNET\docnet-backend\doctor\views.py", line 886, in get
    wallet = doctor.wallet.first()
             ^^^^^^^^^^^^^^^^^^^
AttributeError: 'Wallet' object has no attribute 'first'
ERROR 2025-07-19 19:19:48,172 log 18072 3732 Internal Server Error: /doctor/doctor-analytics/
Traceback (most recent call last):
  File "D:\DOCNET\docnet-backend\venv\Lib\site-packages\asgiref\sync.py", line 518, in thread_handler
    raise exc_info[1]
  File "D:\DOCNET\docnet-backend\venv\Lib\site-packages\django\core\handlers\exception.py", line 42, in inner
    response = await get_response(request)
               ^^^^^^^^^^^^^^^^^^^^^^^^^^^
  File "D:\DOCNET\docnet-backend\venv\Lib\site-packages\asgiref\sync.py", line 518, in thread_handler
    raise exc_info[1]
  File "D:\DOCNET\docnet-backend\venv\Lib\site-packages\django\core\handlers\base.py", line 253, in _get_response_async
    response = await wrapped_callback(
               ^^^^^^^^^^^^^^^^^^^^^^^
        request, *callback_args, **callback_kwargs
        ^^^^^^^^^^^^^^^^^^^^^^^^^^^^^^^^^^^^^^^^^^
    )
    ^
  File "D:\DOCNET\docnet-backend\venv\Lib\site-packages\asgiref\sync.py", line 468, in __call__
    ret = await asyncio.shield(exec_coro)
          ^^^^^^^^^^^^^^^^^^^^^^^^^^^^^^^
  File "D:\DOCNET\docnet-backend\venv\Lib\site-packages\asgiref\current_thread_executor.py", line 40, in run
    result = self.fn(*self.args, **self.kwargs)
  File "D:\DOCNET\docnet-backend\venv\Lib\site-packages\asgiref\sync.py", line 522, in thread_handler
    return func(*args, **kwargs)
  File "D:\DOCNET\docnet-backend\venv\Lib\site-packages\django\views\decorators\csrf.py", line 65, in _view_wrapper
    return view_func(request, *args, **kwargs)
  File "D:\DOCNET\docnet-backend\venv\Lib\site-packages\django\views\generic\base.py", line 104, in view
    return self.dispatch(request, *args, **kwargs)
           ~~~~~~~~~~~~~^^^^^^^^^^^^^^^^^^^^^^^^^^
  File "D:\DOCNET\docnet-backend\venv\Lib\site-packages\rest_framework\views.py", line 515, in dispatch
    response = self.handle_exception(exc)
  File "D:\DOCNET\docnet-backend\venv\Lib\site-packages\rest_framework\views.py", line 475, in handle_exception
    self.raise_uncaught_exception(exc)
    ~~~~~~~~~~~~~~~~~~~~~~~~~~~~~^^^^^
  File "D:\DOCNET\docnet-backend\venv\Lib\site-packages\rest_framework\views.py", line 486, in raise_uncaught_exception
    raise exc
  File "D:\DOCNET\docnet-backend\venv\Lib\site-packages\rest_framework\views.py", line 512, in dispatch
    response = handler(request, *args, **kwargs)
  File "D:\DOCNET\docnet-backend\doctor\views.py", line 886, in get
    wallet = doctor.wallet.first()
             ^^^^^^^^^^^^^^^^^^^
AttributeError: 'Wallet' object has no attribute 'first'
ERROR 2025-07-19 19:21:25,829 log 18512 17904 Internal Server Error: /doctor/doctor-analytics/
Traceback (most recent call last):
  File "D:\DOCNET\docnet-backend\venv\Lib\site-packages\asgiref\sync.py", line 518, in thread_handler
    raise exc_info[1]
  File "D:\DOCNET\docnet-backend\venv\Lib\site-packages\django\core\handlers\exception.py", line 42, in inner
    response = await get_response(request)
               ^^^^^^^^^^^^^^^^^^^^^^^^^^^
  File "D:\DOCNET\docnet-backend\venv\Lib\site-packages\asgiref\sync.py", line 518, in thread_handler
    raise exc_info[1]
  File "D:\DOCNET\docnet-backend\venv\Lib\site-packages\django\core\handlers\base.py", line 253, in _get_response_async
    response = await wrapped_callback(
               ^^^^^^^^^^^^^^^^^^^^^^^
        request, *callback_args, **callback_kwargs
        ^^^^^^^^^^^^^^^^^^^^^^^^^^^^^^^^^^^^^^^^^^
    )
    ^
  File "D:\DOCNET\docnet-backend\venv\Lib\site-packages\asgiref\sync.py", line 468, in __call__
    ret = await asyncio.shield(exec_coro)
          ^^^^^^^^^^^^^^^^^^^^^^^^^^^^^^^
  File "D:\DOCNET\docnet-backend\venv\Lib\site-packages\asgiref\current_thread_executor.py", line 40, in run
    result = self.fn(*self.args, **self.kwargs)
  File "D:\DOCNET\docnet-backend\venv\Lib\site-packages\asgiref\sync.py", line 522, in thread_handler
    return func(*args, **kwargs)
  File "D:\DOCNET\docnet-backend\venv\Lib\site-packages\django\views\decorators\csrf.py", line 65, in _view_wrapper
    return view_func(request, *args, **kwargs)
  File "D:\DOCNET\docnet-backend\venv\Lib\site-packages\django\views\generic\base.py", line 104, in view
    return self.dispatch(request, *args, **kwargs)
           ~~~~~~~~~~~~~^^^^^^^^^^^^^^^^^^^^^^^^^^
  File "D:\DOCNET\docnet-backend\venv\Lib\site-packages\rest_framework\views.py", line 515, in dispatch
    response = self.handle_exception(exc)
  File "D:\DOCNET\docnet-backend\venv\Lib\site-packages\rest_framework\views.py", line 475, in handle_exception
    self.raise_uncaught_exception(exc)
    ~~~~~~~~~~~~~~~~~~~~~~~~~~~~~^^^^^
  File "D:\DOCNET\docnet-backend\venv\Lib\site-packages\rest_framework\views.py", line 486, in raise_uncaught_exception
    raise exc
  File "D:\DOCNET\docnet-backend\venv\Lib\site-packages\rest_framework\views.py", line 512, in dispatch
    response = handler(request, *args, **kwargs)
  File "D:\DOCNET\docnet-backend\doctor\views.py", line 886, in get
    wallet = doctor.wallet.first()
             ^^^^^^^^^^^^^^^^^^^
AttributeError: 'Wallet' object has no attribute 'first'
ERROR 2025-07-19 19:21:25,925 log 18512 17904 Internal Server Error: /doctor/doctor-analytics/
Traceback (most recent call last):
  File "D:\DOCNET\docnet-backend\venv\Lib\site-packages\asgiref\sync.py", line 518, in thread_handler
    raise exc_info[1]
  File "D:\DOCNET\docnet-backend\venv\Lib\site-packages\django\core\handlers\exception.py", line 42, in inner
    response = await get_response(request)
               ^^^^^^^^^^^^^^^^^^^^^^^^^^^
  File "D:\DOCNET\docnet-backend\venv\Lib\site-packages\asgiref\sync.py", line 518, in thread_handler
    raise exc_info[1]
  File "D:\DOCNET\docnet-backend\venv\Lib\site-packages\django\core\handlers\base.py", line 253, in _get_response_async
    response = await wrapped_callback(
               ^^^^^^^^^^^^^^^^^^^^^^^
        request, *callback_args, **callback_kwargs
        ^^^^^^^^^^^^^^^^^^^^^^^^^^^^^^^^^^^^^^^^^^
    )
    ^
  File "D:\DOCNET\docnet-backend\venv\Lib\site-packages\asgiref\sync.py", line 468, in __call__
    ret = await asyncio.shield(exec_coro)
          ^^^^^^^^^^^^^^^^^^^^^^^^^^^^^^^
  File "D:\DOCNET\docnet-backend\venv\Lib\site-packages\asgiref\current_thread_executor.py", line 40, in run
    result = self.fn(*self.args, **self.kwargs)
  File "D:\DOCNET\docnet-backend\venv\Lib\site-packages\asgiref\sync.py", line 522, in thread_handler
    return func(*args, **kwargs)
  File "D:\DOCNET\docnet-backend\venv\Lib\site-packages\django\views\decorators\csrf.py", line 65, in _view_wrapper
    return view_func(request, *args, **kwargs)
  File "D:\DOCNET\docnet-backend\venv\Lib\site-packages\django\views\generic\base.py", line 104, in view
    return self.dispatch(request, *args, **kwargs)
           ~~~~~~~~~~~~~^^^^^^^^^^^^^^^^^^^^^^^^^^
  File "D:\DOCNET\docnet-backend\venv\Lib\site-packages\rest_framework\views.py", line 515, in dispatch
    response = self.handle_exception(exc)
  File "D:\DOCNET\docnet-backend\venv\Lib\site-packages\rest_framework\views.py", line 475, in handle_exception
    self.raise_uncaught_exception(exc)
    ~~~~~~~~~~~~~~~~~~~~~~~~~~~~~^^^^^
  File "D:\DOCNET\docnet-backend\venv\Lib\site-packages\rest_framework\views.py", line 486, in raise_uncaught_exception
    raise exc
  File "D:\DOCNET\docnet-backend\venv\Lib\site-packages\rest_framework\views.py", line 512, in dispatch
    response = handler(request, *args, **kwargs)
  File "D:\DOCNET\docnet-backend\doctor\views.py", line 886, in get
    wallet = doctor.wallet.first()
             ^^^^^^^^^^^^^^^^^^^
AttributeError: 'Wallet' object has no attribute 'first'
INFO 2025-07-19 19:22:29,008 views 13092 16600 GET request for emergency status from user: Jibin (doctor)
INFO 2025-07-19 19:22:29,014 views 13092 16600 Found profile for Jibin (doctor): emergency_status=True
INFO 2025-07-19 19:22:29,062 views 13092 18352 GET request for emergency status from user: Jibin (doctor)
INFO 2025-07-19 19:22:29,065 views 13092 18352 Found profile for Jibin (doctor): emergency_status=True
INFO 2025-07-19 19:22:29,344 views 13092 22240 GET request for emergency status from user: Jibin (doctor)
INFO 2025-07-19 19:22:29,351 views 13092 22240 Found profile for Jibin (doctor): emergency_status=True
INFO 2025-07-19 19:22:29,426 views 13092 17800 GET request for emergency status from user: Jibin (doctor)
INFO 2025-07-19 19:22:29,433 views 13092 17800 Found profile for Jibin (doctor): emergency_status=True
INFO 2025-07-19 19:22:36,461 views 13092 412 GET request for emergency status from user: Jibin (doctor)
INFO 2025-07-19 19:22:36,465 views 13092 412 Found profile for Jibin (doctor): emergency_status=True
INFO 2025-07-19 19:22:36,627 views 13092 7164 GET request for emergency status from user: Jibin (doctor)
INFO 2025-07-19 19:22:36,634 views 13092 7164 Found profile for Jibin (doctor): emergency_status=True
INFO 2025-07-19 19:22:36,711 views 13092 7832 GET request for emergency status from user: Jibin (doctor)
INFO 2025-07-19 19:22:36,720 views 13092 7832 Found profile for Jibin (doctor): emergency_status=True
INFO 2025-07-19 19:22:36,782 views 13092 9324 GET request for emergency status from user: Jibin (doctor)
INFO 2025-07-19 19:22:36,787 views 13092 9324 Found profile for Jibin (doctor): emergency_status=True
INFO 2025-07-19 19:22:38,723 views 13092 15296 GET request for emergency status from user: Jibin (doctor)
INFO 2025-07-19 19:22:38,726 views 13092 15296 Found profile for Jibin (doctor): emergency_status=True
INFO 2025-07-19 19:22:38,895 views 13092 20624 GET request for emergency status from user: Jibin (doctor)
INFO 2025-07-19 19:22:38,899 views 13092 20624 Found profile for Jibin (doctor): emergency_status=True
INFO 2025-07-19 19:22:39,068 views 13092 21216 GET request for emergency status from user: Jibin (doctor)
INFO 2025-07-19 19:22:39,072 views 13092 21216 Found profile for Jibin (doctor): emergency_status=True
INFO 2025-07-19 19:22:39,238 views 13092 20244 GET request for emergency status from user: Jibin (doctor)
INFO 2025-07-19 19:22:39,241 views 13092 20244 Found profile for Jibin (doctor): emergency_status=True
WARNING 2025-07-19 19:22:46,218 log 13092 18780 Not Found: /doctor/withdrawal/request/
INFO 2025-07-19 19:23:57,313 views 16844 20444 GET request for emergency status from user: Jibin (doctor)
INFO 2025-07-19 19:23:57,317 views 16844 20444 Found profile for Jibin (doctor): emergency_status=True
INFO 2025-07-19 19:23:59,517 views 16844 13456 GET request for emergency status from user: Jibin (doctor)
INFO 2025-07-19 19:23:59,527 views 16844 13456 Found profile for Jibin (doctor): emergency_status=True
INFO 2025-07-19 19:23:59,691 views 16844 11640 GET request for emergency status from user: Jibin (doctor)
INFO 2025-07-19 19:23:59,699 views 16844 11640 Found profile for Jibin (doctor): emergency_status=True
INFO 2025-07-19 19:23:59,860 views 16844 11804 GET request for emergency status from user: Jibin (doctor)
INFO 2025-07-19 19:23:59,877 views 16844 11804 Found profile for Jibin (doctor): emergency_status=True
INFO 2025-07-19 19:23:59,956 views 16844 5776 GET request for emergency status from user: Jibin (doctor)
INFO 2025-07-19 19:23:59,961 views 16844 5776 Found profile for Jibin (doctor): emergency_status=True
WARNING 2025-07-19 19:32:17,297 log 16844 17832 Bad Request: /core/admin-withdrawal/13/action/
WARNING 2025-07-19 19:37:23,530 log 16844 17832 Bad Request: /core/admin-withdrawal/13/action/
INFO 2025-07-19 19:43:34,304 views 14068 9280 GET request for emergency status from user: Jibin (doctor)
INFO 2025-07-19 19:43:34,309 views 14068 9280 Found profile for Jibin (doctor): emergency_status=True
INFO 2025-07-19 19:43:37,482 views 14068 8756 GET request for emergency status from user: Jibin (doctor)
INFO 2025-07-19 19:43:37,501 views 14068 8756 Found profile for Jibin (doctor): emergency_status=True
INFO 2025-07-19 19:43:37,617 views 14068 14744 GET request for emergency status from user: Jibin (doctor)
INFO 2025-07-19 19:43:37,624 views 14068 14744 Found profile for Jibin (doctor): emergency_status=True
INFO 2025-07-19 19:43:37,876 views 14068 9180 GET request for emergency status from user: Jibin (doctor)
INFO 2025-07-19 19:43:37,880 views 14068 9180 Found profile for Jibin (doctor): emergency_status=True
INFO 2025-07-19 19:43:37,938 views 14068 20964 GET request for emergency status from user: Jibin (doctor)
INFO 2025-07-19 19:43:37,943 views 14068 20964 Found profile for Jibin (doctor): emergency_status=True
INFO 2025-07-19 19:43:38,086 views 14068 19276 GET request for emergency status from user: Jibin (doctor)
INFO 2025-07-19 19:43:38,089 views 14068 19276 Found profile for Jibin (doctor): emergency_status=True
INFO 2025-07-19 19:43:38,132 views 14068 15324 GET request for emergency status from user: Jibin (doctor)
INFO 2025-07-19 19:43:38,136 views 14068 15324 Found profile for Jibin (doctor): emergency_status=True
INFO 2025-07-19 19:44:22,761 views 14068 14636 GET request for emergency status from user: Jibin (doctor)
INFO 2025-07-19 19:44:22,766 views 14068 14636 Found profile for Jibin (doctor): emergency_status=True
INFO 2025-07-19 19:44:33,355 views 14068 2660 GET request for emergency status from user: Jibin (doctor)
INFO 2025-07-19 19:44:33,359 views 14068 2660 Found profile for Jibin (doctor): emergency_status=True
INFO 2025-07-19 19:44:45,333 views 14068 4540 GET request for emergency status from user: Jibin (doctor)
INFO 2025-07-19 19:44:45,336 views 14068 4540 Found profile for Jibin (doctor): emergency_status=True
INFO 2025-07-19 19:44:51,849 views 14068 18624 GET request for emergency status from user: Jibin (doctor)
INFO 2025-07-19 19:44:51,854 views 14068 18624 Found profile for Jibin (doctor): emergency_status=True
INFO 2025-07-19 19:44:51,930 views 14068 3740 GET request for emergency status from user: Jibin (doctor)
INFO 2025-07-19 19:44:51,935 views 14068 3740 Found profile for Jibin (doctor): emergency_status=True
INFO 2025-07-19 19:44:55,868 views 14068 11204 GET request for emergency status from user: Jibin (doctor)
INFO 2025-07-19 19:44:55,875 views 14068 11204 Found profile for Jibin (doctor): emergency_status=True
INFO 2025-07-19 19:44:56,004 views 14068 15676 GET request for emergency status from user: Jibin (doctor)
INFO 2025-07-19 19:44:56,010 views 14068 15676 Found profile for Jibin (doctor): emergency_status=True
INFO 2025-07-19 19:44:56,065 views 14068 13228 GET request for emergency status from user: Jibin (doctor)
INFO 2025-07-19 19:44:56,069 views 14068 13228 Found profile for Jibin (doctor): emergency_status=True
INFO 2025-07-19 19:44:56,127 views 14068 1772 GET request for emergency status from user: Jibin (doctor)
INFO 2025-07-19 19:44:56,131 views 14068 1772 Found profile for Jibin (doctor): emergency_status=True
ERROR 2025-07-19 19:45:14,171 log 14068 11616 Internal Server Error: /core/admin-withdrawal/13/action/
ERROR 2025-07-19 19:46:24,038 log 9728 18780 Internal Server Error: /core/admin-withdrawal/13/action/
ERROR 2025-07-19 19:48:37,716 log 12088 3320 Internal Server Error: /core/admin-withdrawal/13/action/
ERROR 2025-07-19 19:50:40,833 log 19856 7332 Internal Server Error: /core/admin-withdrawal/13/action/
ERROR 2025-07-19 20:03:20,815 log 16500 6316 Internal Server Error: /core/admin-withdrawal/13/action/
ERROR 2025-07-19 20:05:06,393 log 1832 16712 Internal Server Error: /core/admin-withdrawal/13/action/
ERROR 2025-07-19 20:12:56,874 views 18352 11520 Cashfree response parsing error for withdrawal 13: Invalid token response format
ERROR 2025-07-19 20:12:56,880 log 18352 10024 Internal Server Error: /core/admin-withdrawal/13/action/
ERROR 2025-07-19 20:31:10,402 views 6648 19704 Cashfree response parsing error for withdrawal 13: Payout failed: Invalid request URL or HTTP Method
ERROR 2025-07-19 20:31:10,410 log 6648 1304 Internal Server Error: /core/admin-withdrawal/13/action/
